Workbook

Sheet 前提条件
A1: 姫路市夢前町戸倉 日生学園跡地 33.6ha DC用地検討 前提条件 ※青字は変更可
A3: 項目 | B3: 値 | C3: 備考
A4: 敷地面積（㎡） | B4: 335897.83 | C4: 物件概要書（登記簿）335,897.83㎡ = 101,609坪
A5: うち 屋外運動場（㎡） | B5: 41971 | C5: H6.4.26 基礎調査用資料
A6: うち 建物敷地その他（㎡） | B6: 68600 | C6: 同上
A7: うち 実験実習地＝山林（㎡） | B7: 226694 | C7: 同上。林地開発許可の対象になり得る
A8: 既存建物 延床（㎡） | B8: 27523 | C8: 校舎・体育館・寮・食堂・職員住宅等の合計（同資料）
A9: 募集価格（円） | B9: 1650000000 | C9: 16億5,000万円（坪16,238円）。税込/税抜は要確認
A10: 固定資産税評価 土地（円） | B10: 340000000 | C10: 平場3,000円/㎡＋山林50円/㎡ の想定
A11: 固定資産税評価 建物（円） | B11: 100000000 | C11: 築40年超
A12: 固定資産税率 | B12: 0.014 | C12: 都市計画区域外のため都市計画税なし
A13: 仲介手数料率 | B13: 0.03 | C13: ＋6万円、税込
A14: 登録免許税率（土地） | B14: 0.015
A15: 登録免許税率（建物） | B15: 0.02
A16: 不動産取得税率 | B16: 0.03 | C16: 山林・雑種地は宅地1/2特例なし
A17: その他取得費用（円） | B17: 40000000 | C17: 境界確認・測量・調査
A18: 解体単価（円/坪） | B18: 70000 | C18: RC造 校舎・寮
A19: 解体 追加費用（円） | B19: 150000000 | C19: アスベスト・杭・浄化槽等
A20: 金利（年） | B20: 0.02
A21: 融資手数料率 | B21: 0.005
A23: 平場面積（㎡） | B23: =B5+B6
A24: 募集価格 円/㎡（全体） | B24: =B9/B4
A25: 募集価格 円/㎡（平場換算・山林ゼロ評価） | B25: =B9/B23
A26: 解体費（円） | B26: =B8/3.30579*B18+B19
A27: 固都税 年額（円） | B27: =(B10+B11)*B12
A28: 取得諸経費 合計（円） | B28: =(B9*B13+60000)*1.1+B10*B14+B11*B15+(B10+B11)*B16+B17

Sheet DC事業
A1: データセンター開発事業 収支（ホールセール型） ※青字は変更可。前提条件シートを参照
A3: 入力 | B3: 値 | C3: 備考
A4: IT負荷（MW） | B4: 50 | C4: 受電容量は PUE 倍
A5: PUE | B5: 1.3
A6: capex 円/MW（建屋・設備） | B6: 2000000000 | C6: 土地・造成・系統負担金を除く。東京はUSD15.2/W≒23億/MW（T&T 2025）
A7: 造成・インフラ（円） | B7: 500000000 | C7: 整地・調整池・構内道路・上下水
A8: 系統接続・工事費負担金（円） | B8: 2000000000 | C8: 接続検討の回答で確定。数億〜数十億
A9: 通信引込（円） | B9: 300000000 | C9: 冗長ダークファイバー
A10: 設計監理率（capex比） | B10: 0.04
A11: 予備費率（capex比） | B11: 0.05
A12: 受電待ち期間（年） | B12: 3 | C12: 接続検討〜供給開始のリードタイム
A13: 工期（月） | B13: 30
A14: 賃料 円/kW/月 | B14: 20000 | C14: 電気代は実費転嫁。東京ホールセール2.5〜3.0万の想定に対し地方は1.5〜2.2万
A15: 稼働率 | B15: 0.9
A16: 運営費率（賃料比） | B16: 0.2 | C16: 保守・保険・管理
A17: 建物・償却資産税率（capex比） | B17: 0.006
A18: キャップレート | B18: 0.05 | C18: 東京DC 4.3〜4.5%に対し地方 +0.5〜1.0pt
A19: 開発利益率（総事業費比） | B19: 0.15
A20: 土地価格（円） | B20: 1650000000 | C20: 募集価格。指値検討時はここを変更
A22: 費用項目 | B22: 金額（円） | C22: 計算
A23: 土地代 | B23: =B20
A24: 取得諸経費 | B24: =(B20*前提条件!B13+60000)*1.1+前提条件!B10*前提条件!B14+前提条件!B11*前提条件!B15+(前提条件!B10+前提条件!B11)*前提条件!B16+前提条件!B17 | C24: 仲介・登免税・取得税・その他
A25: 既存建物解体 | B25: =前提条件!B8/3.30579*前提条件!B18+前提条件!B19
A26: DC建屋・設備 | B26: =B4*B6 | C26: MW × capex/MW
A27: 造成・インフラ | B27: =B7
A28: 系統接続・工事費負担金 | B28: =B8
A29: 通信引込 | B29: =B9
A30: 設計監理 | B30: =B26*B10
A31: 予備費 | B31: =B26*B11
A32: 固都税（事業期間） | B32: =(前提条件!B10+前提条件!B11)*前提条件!B12*(B12+B13/12) | C32: 受電待ち＋工期
A33: 金利・融資手数料 | B33: =(B23+B24+B25)*前提条件!B20*(B12+B13/12)+(B26+B27+B28+B29+B30+B31)*前提条件!B20*(B13/12)/2+SUM(B23:B31)*前提条件!B21 | C33: 土地側は全期間、建設側は工期の1/2
A34: 総事業費 | B34: =SUM(B23:B33)
A36: 収支指標 | B36: 値 | C36: 計算
A37: 受電容量（MW） | B37: =B4*B5
A38: 年間賃料収入 | B38: =B4*1000*B14*12*B15 | C38: IT kW × 賃料 × 12 × 稼働率
A39: 年間運営費・固都税 | B39: =B38*B16+B26*B17+(前提条件!B10+前提条件!B11)*前提条件!B12
A40: NOI | B40: =B38-B39
A41: NOI利回り（総事業費比） | B41: =B40/B34
A42: 収益価格 | B42: =B40/B18 | C42: NOI ÷ cap
A43: 含み損益（収益価格−総事業費） | B43: =B42-B34
...

Sheet 規模別比較
A1: DC 規模別の収支（himeji_dc.py の計算値。賃料2.0万円/kW/月・cap5.0%・capex20億/MW）
A3: 項目 | B3: 郊外型ミドル 20MW | C3: 郊外型ラージ 50MW | D3: キャンパス型 100MW（平場11ha上限）
A4: 土地代 | B4: 16.5 | C4: 16.5 | D4: 16.5
A5: 仲介手数料(税込) | B5: 0.54516 | C5: 0.54516 | D5: 0.54516
A6: 登録免許税 | B6: 0.071 | C6: 0.071 | D6: 0.071
A7: 不動産取得税 | B7: 0.132 | C7: 0.132 | D7: 0.132
A8: その他取得費用 | B8: 0.4 | C8: 0.4 | D8: 0.4
A9: 既存建物解体 | B9: 7.3279867 | C9: 7.3279867 | D9: 7.3279867
A10: DC建屋・設備 | B10: 400 | C10: 1000 | D10: 2000
A11: 造成・インフラ | B11: 4 | C11: 5 | D11: 8
A12: 系統接続・工事費負担金 | B12: 12 | C12: 20 | D12: 40
A13: 通信引込 | B13: 3 | C13: 3 | D13: 3
A14: 設計監理 | B14: 16 | C14: 40 | D14: 80
A15: 予備費 | B15: 20 | C15: 50 | D15: 100
... A30: 総事業費/MW | B30: 24.84186 | C30: 23.594544 | D30: 23.489883

Sheet 感度分析
A1: 感度分析（50MW）
A3: ① 開発利益率 行=賃料(円/kW/月), 列=capex(億/MW) cap5.0%
A4: 賃料＼capex | B4: 16億/MW | C4: 20億/MW | D4: 24億/MW
A5: 15000 | B5: 0.25500844 | C5: -0.0042036867 | D5: -0.18052063
A6: 18000 | B6: 0.52636886 | C6: 0.21550812 | D6: 0.0040596237
A7: 20000 | B7: 0.7072758 | C7: 0.36198266 | D7: 0.12711313
A8: 22000 | B8: 0.88818275 | C8: 0.5084572 | D8: 0.25016663
A9: 25000 | B9: 1.1595432 | C9: 0.72816902 | D9: 0.43474689
A12: ② 含み損益（億円） 行=キャップレート, 列=賃料(円/kW/月) capex20億/MW
A13: cap＼賃料 | B13: 15,000 | C13: 18,000 | D13: 20,000 | E13: 22,000 | F13: 25,000
A14: 0.045 | B14: 125.57057 | C14: 413.57057 | D14: 605.57057 | E14: 797.57057 | F14: 1085.5706
A15: 0.05 | B15: -4.9592035 | C15: 254.2408 | D15: 427.0408 | E15: 599.8408 | F15: 859.0408
A16: 0.055 | B16: -111.75629 | C16: 123.88007 | D16: 280.97098 | E16: 438.06189 | F16: 673.69825
A17: 0.06 | B17: -200.75387 | C17: 15.24613 | D17: 159.24613 | E17: 303.24613 | F17: 519.24613

Sheet 残余法
A1: 残余法: DC事業が土地に払える理論上限（開発利益15%控除後）と DC以外の出口の価格
A3: DCケース | B3: 土地価格上限 | C3: 円/㎡ | D3: 備考
A4: 郊外型ミドル 20MW（賃料2.0万） | B4: 69.804486 | C4: 20781.464 | D4: 電力・テナントが確保できる前提の理論値。土地代は総事業費の1〜2%
A5: 郊外型ラージ 50MW（賃料2.0万） | B5: 205.30301 | C5: 61120.671 | D5: 電力・テナントが確保できる前提の理論値。土地代は総事業費の1〜2%
A6: キャンパス型 100MW（平場11ha上限）（賃料2.0万） | B6: 397.29253 | C6: 118277.79 | D6: 電力・テナントが確保できる前提の理論値。土地代は総事業費の1〜2%
A7: 郊外型ラージ 50MW（賃料1.8万） | B7: 74.845011 | C7: 22282.076 | D7: 電力・テナントが確保できる前提の理論値。土地代は総事業費の1〜2%
A8: 郊外型ラージ 50MW（賃料1.5万） | B8: 成立せず | C8: － | D8: 電力・テナントが確保できる前提の理論値。土地代は総事業費の1〜2%
A9: 郊外型ラージ 50MW（賃料2.0万・cap6.0%・capex24億） | B9: 成立せず | C9: － | D9: 電力・テナントが確保できる前提の理論値。土地代は総事業費の1〜2%
A11: DC以外の出口 | B11: 土地建物の価格 | C11: 年間NOI | D11: 備考
A12: 現況一括賃貸（研修・合宿・学校用途） | B12: 2.8342857 | C12: 0.3384 | D12: 開発許可不要。借主確保が前提
A13: 太陽光（運動場4.2haの地代・建物は残置） | B13: 0.16251167 | C13: 0.0097507 | D13: 固都税を地代が辛うじて上回る水準。系統空き容量の確認要
A14: 系統用蓄電池（2.5ha地代・残地未利用） | B14: 2.3066667 | C14: 0.1384 | D14: 運動場の一部で成立。特高接続が前提で、DCと同じ電力論点
A15: 産業用地分譲（平場11haを工場・倉庫用地に） | B15: -3.1109548 | C15: 0 | D15: 売上11.1億から解体・造成・利益15%を引いた残余。開発許可（1ha超）要
A16: 山林・現況保有 | B16: 0.779549 | C16: -0.0616 | D16: 地目山林・原野の素地価格
A18: 募集価格 | B18: 16.5 | C18: 4912.208

Sheet 保有コスト
A1: 16.5億円で取得し、受電・許認可の一次回答を待つ場合の保有コスト（金利2%・固都税・管理費500万/年）
A3: 年 | B3: 年額 | C3: 累計（取得諸経費含む） | D3: 簿価合計（土地代＋累計）
A4: 1 | B4: 0.4416 | C4: 1.58976 | D4: 18.08976
A5: 2 | B5: 0.4416 | C5: 2.03136 | D5: 18.53136
A6: 3 | B6: 0.4416 | C6: 2.47296 | D6: 18.97296
A7: 4 | B7: 0.4416 | C7: 2.91456 | D7: 19.41456
A8: 5 | B8: 0.4416 | C8: 3.35616 | D8: 19.85616
